Workbook

Sheet README
B2: BrewTrack — Coffee Shop Sales Performance Analysis
B4: PROJECT OVERVIEW
B5: A small Excel Data Analyst portfolio project analyzing 3 months (Jun–Aug 2026) of sales across 4 outlets of a fictional coffee shop chain, BrewTrack. Built to demonstrate data cleaning, formula-based analysis, summary tables, and dashboard design at a fresher/beginner-to-intermediate level.
B7: BUSINESS PROBLEM
B8: BrewTrack's owner has been exporting daily sales from the POS billing system into a spreadsheet but has never analyzed it. This project answers: what's selling, which outlet performs best, what a typical order looks like, and where to focus attention next quarter.
B10: OBJECTIVES
B11: • Clean 3 months of raw POS export data (200 rows, with realistic data-quality issues)
B12: • Calculate core KPIs: Total Sales, Total Profit, Profit Margin, Average Order Value, Total Orders
B13: • Identify best-selling products and the most profitable category
B14: • Compare outlet performance
B15: • Spot the monthly sales trend across the quarter
B16: • Build summary tables (PivotTable-style) answering every business question
... B42: Author: [Your Name]

Sheet Raw_Data
A1: Raw_Data — As exported from the POS billing system (unedited)
A2: Do not edit this sheet. This is the original export, kept intact so the cleaning steps on the Cleaned_Data tab can be verified against it.
A4: Order_ID | B4: Order_Date | C4: Outlet | D4: Product | E4: Category | F4: Quantity | G4: Unit_Price | H4: Cost | I4: Payment_Method | J4: Order_Status
A5: ORD1145 | B5: 46214 | C5: Koramangala | D5: Danish Pastry | E5: Bakery | F5: 1 | G5: 160 | H5: 78 | I5: Cash | J5: Cancelled
A6: ORD1010 | B6: 46179 | C6: Koramangala | D6: muffin | E6: Bakery | F6: 1 | G6: 130 | H6: 57 | I6: UPI | J6: Completed
A7: ORD1018 | B7: 46190 | C7: koramangala | D7: Veg Puff | E7: Snacks | F7: 3 | G7: 80 | H7: 125 | I7: Card | J7: Completed
A8: ORD1021 | B8: 46242 | C8: Koramangala | D8: Brownie | E8: Bakery | F8: 2 | G8: 150 | H8: 123 | I8: UPI | J8: Completed
A9: ORD1046 | B9: 46193 | C9: Whitefield | D9: Hot Chocolate | E9: Hot Beverages | F9: 1 | G9: 170 | H9: 62 | I9: UPI | J9: Completed
A10: ORD1007 | B10: 46233 | C10: hsr layout | D10: Brownie | E10: Bakery | F10: 1 | G10: 150 | H10: 74 | I10: Cash | J10: Completed
A11: ORD1053 | B11: 46262 | C11: Indiranagar | D11: Sandwich | E11: Snacks | F11: 3 | G11: 190 | H11: 259 | I11: UPI | J11: Completed
A12: ORD1092 | B12: 46204 | C12: Whitefield | D12: Garlic Bread | E12: Snacks | F12: 2 | G12: 150 | H12: 141 | I12: UPI | J12: Completed
A13: ORD1130 | B13: 46198 | C13: Whitefield | D13: Espresso | E13: Hot Beverages | F13: 1 | G13: 150 | H13: 67 | I13: UPI | J13: Completed
A14: ORD1184 | B14: 46255 | C14: Koramangala | D14: Croissant | E14: Bakery | F14: 2 | G14: 140 | H14: 116 | J14: Completed
A15: ORD1022 | B15: 46255 | C15: Whitefield | D15: Brownie | E15: Bakery | F15: 2 | G15: 150 | H15: 137 | I15: UPI | J15: Completed
A16: ORD1043 | B16: 46238 | C16: indiranagar | D16: Iced Tea | E16: Cold Beverages | F16: 2 | G16: 150 | H16: 130 | I16: UPI | J16: Cancelled
A17: ORD1106 | B17: 46213 | C17: Koramangala | D17: Cappuccino | E17: Hot Beverages | F17: 1 | G17: 180 | H17: 79 | I17: Cash | J17: Completed
A18: ORD1146 | B18: 46255 | C18: Indiranagar | D18: Danish Pastry | E18: Bakery | F18: 2 | G18: 160 | H18: 136 | I18: UPI | J18: Completed
A19: ORD1088 | B19: 46221 | C19: HSR Layout | D19: Cappuccino | E19: Hot Beverages | F19: 3 | G19: 180 | H19: 223 | I19: Card | J19: Cancelled
A20: ORD1153 | B20: 46214 | C20: Koramangala | D20: Latte | E20: Hot Beverages | F20: 2 | G20: 190 | H20: 167 | I20: Cash | J20: Completed
A21: ORD1125 | B21: 46244 | C21: Whitefield | D21: COLD BREW | E21: Cold Beverages | F21: 4 | G21: 220 | H21: 412 | I21: Card | J21: Completed
A22: ORD1093 | B22: 46200 | C22: HSR Layout | D22: Frappe | E22: Cold Beverages | F22: 2 | G22: 240 | H22: 198 | I22: Cash | J22: Completed
A23: ORD1102 | B23: 46178 | C23: Whitefield | D23: Hot Chocolate | E23: Hot Beverages | F23: 2 | G23: 170 | H23: 137 | I23: UPI | J23: Completed
A24: ORD1014 | B24: 46224 | C24: HSR Layout | D24: Garlic Bread | E24: Snacks | F24: 1 | G24: 150 | H24: 72 | I24: UPI | J24: Cancelled
A25: ORD1109 | B25: 03/08/2026 | C25: Indiranagar | D25: Croissant | E25: Bakery | F25: 2 | G25: 140 | H25: 119 | I25: UPI | J25: Completed
A26: ORD1076 | B26: 46192 | C26: Whitefield | D26: Iced Tea | E26: Cold Beverages | F26: 2 | G26: 150 | H26: 135 | I26: Cash | J26: Completed
A27: ORD1041 | B27: 46215 | C27: HSR Layout | D27: Filter Coffee | E27: Hot Beverages | F27: 3 | G27: 120 | H27: 128 | I27: UPI | J27: Completed
A28: ORD1148 | B28: 46198 | C28: Koramangala | D28: Latte | E28: Hot Beverages | F28: 2 | G28: 190 | H28: 145 | I28: UPI | J28: Completed
A29: ORD1192 | B29: 46263 | C29: Koramangala | D29: Muffin | E29: Bakery | F29: 1 | G29: 130 | H29: 58 | I29: UPI | J29: Cancelled
A30: ORD1193 | B30: 46185 | C30: HSR Layout | D30: Cappuccino | E30: Hot Beverage | F30: 1 | G30: 180 | H30: 68 | I30: UPI | J30: Completed
A31: ORD1195 | B31: 46251 | C31: Koramangala | D31: Brownie | E31: Bakery | F31: 2 | G31: 150 | H31: 139 | I31: Card | J31: Completed
A32: ORD1118 | B32: 46254 | C32: hsr layout | D32: Latte | E32: Hot Beverages | F32: 1 | G32: 190 | H32: 75 | I32: Card | J32: Completed
A33: ORD1003 | B33: 46181 | C33: Koramangala | D33: Frappe | E33: Cold Beverages | F33: 2 | G33: 240 | H33: 210 | I33: UPI | J33: Completed
A34: ORD1132 | B34: 46221 | C34: Koramangala | D34: Croissant | E34: Bakery | F34: 1 | G34: 140 | H34: 57 | I34: Cash | J34: Completed
A35: ORD1020 | B35: 46200 | C35: HSR Layout | D35: Cold Brew | E35: Cold Beverages | F35: 1 | G35: 220 | H35: 97 | I35: UPI | J35: Completed
A36: ORD1144 | B36: 46223 | C36: HSR Layout | D36: Iced Latte | E36: Cold Beverages | F36: 1 | G36: 200 | H36: 93 | I36: UPI | J36: Cancelled
A37: ORD1148 | B37: 46198 | C37: Koramangala | D37: Latte | E37: Hot Beverages | F37: 2 | G37: 190 | H37: 145 | I37: UPI | J37: Completed
A38: ORD1023 | B38: 46233 | C38: HSR Layout | D38: Garlic Bread | E38: Snacks | F38: 1 | G38: 150 | H38: 66 | I38: Cash | J38: Completed
A39: ORD1103 | B39: 13/06/2026 | C39: Koramangala | D39: Croissant | E39: Bakery | F39: 2 | G39: 140 | H39: 132 | I39: UPI | J39: Completed
A40: ORD1061 | B40: 46255 | C40: Indiranagar | D40: Danish Pastry | E40: bakery | F40: 4 | G40: 160 | H40: 331 | I40: Card | J40: Completed
A41: ORD1137 | B41: 46178 | C41: HSR Layout | D41: Garlic Bread | E41: Snacks | F41: 1 | G41: 150 | H41: 65 | I41: UPI | J41: Completed
...

Sheet Cleaned_Data
A1: Cleaned_Data — Every column below is a formula pulling from Raw_Data (nothing is retyped by hand)
A2: Cleaning log: 3 duplicate Order_IDs removed (kept first occurrence) · text/casing standardized · 2 mismatched date formats reconstructed · 3 missing Quantity values defaulted to 1 (flagged) · 7 blank Payment_Method values labeled 'Not Specified'.
A4: Order ID | B4: Order Date | C4: Outlet | D4: Product | E4: Category | F4: Quantity | G4: Unit Price | H4: Sales | I4: Cost | J4: Profit | K4: Profit Margin | L4: Month | M4: Year | N4: Payment Method | O4: Order Status | P4: Order Status Category | S4: Cleaning Reference Tables (used by formulas — do not delete)
A5: =Raw_Data!A5 -> ORD1145 | B5: =IF(ISNUMBER(Raw_Data!B5),Raw_Data!B5,DATE(VALUE(RIGHT(Raw_Data!B5,4)),VALUE(MID(Raw_Data!B5,4,2)),VALUE(LEFT(Raw_Data!B5,2)))) -> 46214 | C5: =IFERROR(INDEX($T$10:$T$11,MATCH(PROPER(TRIM(Raw_Data!C5)),$S$10:$S$11,0)),PROPER(TRIM(Raw_Data!C5))) -> Koramangala | D5: =PROPER(TRIM(Raw_Data!D5)) -> Danish Pastry | E5: =IFERROR(INDEX($T$6:$T$7,MATCH(PROPER(TRIM(Raw_Data!E5)),$S$6:$S$7,0)),PROPER(TRIM(Raw_Data!E5))) -> Bakery | F5: =IF(TRIM(Raw_Data!F5&"")="",1,VALUE(Raw_Data!F5)) -> 1 | G5: =VALUE(Raw_Data!G5) -> 160 | H5: =F5*G5 -> 160 | I5: =VALUE(Raw_Data!H5) -> 78 | J5: =H5-I5 -> 82 | K5: =IFERROR(J5/H5,0) -> 0.5125 | L5: =TEXT(B5,"MMM-YYYY") -> Jul-2026 | M5: =YEAR(B5) -> 2026 | N5: =IF(TRIM(Raw_Data!I5&"")="","Not Specified",TRIM(Raw_Data!I5)) -> Cash | O5: =PROPER(TRIM(Raw_Data!J5)) -> Cancelled | P5: =IF(O5="Completed","Completed","Not Completed") -> Not Completed | S5: Category variant | T5: Standardized to
A6: =Raw_Data!A6 -> ORD1010 | B6: =IF(ISNUMBER(Raw_Data!B6),Raw_Data!B6,DATE(VALUE(RIGHT(Raw_Data!B6,4)),VALUE(MID(Raw_Data!B6,4,2)),VALUE(LEFT(Raw_Data!B6,2)))) -> 46179 | C6: =IFERROR(INDEX($T$10:$T$11,MATCH(PROPER(TRIM(Raw_Data!C6)),$S$10:$S$11,0)),PROPER(TRIM(Raw_Data!C6))) -> Koramangala | D6: =PROPER(TRIM(Raw_Data!D6)) -> Muffin | E6: =IFERROR(INDEX($T$6:$T$7,MATCH(PROPER(TRIM(Raw_Data!E6)),$S$6:$S$7,0)),PROPER(TRIM(Raw_Data!E6))) -> Bakery | F6: =IF(TRIM(Raw_Data!F6&"")="",1,VALUE(Raw_Data!F6)) -> 1 | G6: =VALUE(Raw_Data!G6) -> 130 | H6: =F6*G6 -> 130 | I6: =VALUE(Raw_Data!H6) -> 57 | J6: =H6-I6 -> 73 | K6: =IFERROR(J6/H6,0) -> 0.56153846 | L6: =TEXT(B6,"MMM-YYYY") -> Jun-2026 | M6: =YEAR(B6) -> 2026 | N6: =IF(TRIM(Raw_Data!I6&"")="","Not Specified",TRIM(Raw_Data!I6)) -> UPI | O6: =PROPER(TRIM(Raw_Data!J6)) -> Completed | P6: =IF(O6="Completed","Completed","Not Completed") -> Completed | S6: Hot Beverage | T6: Hot Beverages
A7: =Raw_Data!A7 -> ORD1018 | B7: =IF(ISNUMBER(Raw_Data!B7),Raw_Data!B7,DATE(VALUE(RIGHT(Raw_Data!B7,4)),VALUE(MID(Raw_Data!B7,4,2)),VALUE(LEFT(Raw_Data!B7,2)))) -> 46190 | C7: =IFERROR(INDEX($T$10:$T$11,MATCH(PROPER(TRIM(Raw_Data!C7)),$S$10:$S$11,0)),PROPER(TRIM(Raw_Data!C7))) -> Koramangala | D7: =PROPER(TRIM(Raw_Data!D7)) -> Veg Puff | E7: =IFERROR(INDEX($T$6:$T$7,MATCH(PROPER(TRIM(Raw_Data!E7)),$S$6:$S$7,0)),PROPER(TRIM(Raw_Data!E7))) -> Snacks | F7: =IF(TRIM(Raw_Data!F7&"")="",1,VALUE(Raw_Data!F7)) -> 3 | G7: =VALUE(Raw_Data!G7) -> 80 | H7: =F7*G7 -> 240 | I7: =VALUE(Raw_Data!H7) -> 125 | J7: =H7-I7 -> 115 | K7: =IFERROR(J7/H7,0) -> 0.47916667 | L7: =TEXT(B7,"MMM-YYYY") -> Jun-2026 | M7: =YEAR(B7) -> 2026 | N7: =IF(TRIM(Raw_Data!I7&"")="","Not Specified",TRIM(Raw_Data!I7)) -> Card | O7: =PROPER(TRIM(Raw_Data!J7)) -> Completed | P7: =IF(O7="Completed","Completed","Not Completed") -> Completed | S7: Cold Beverage | T7: Cold Beverages
A8: =Raw_Data!A8 -> ORD1021 | B8: =IF(ISNUMBER(Raw_Data!B8),Raw_Data!B8,DATE(VALUE(RIGHT(Raw_Data!B8,4)),VALUE(MID(Raw_Data!B8,4,2)),VALUE(LEFT(Raw_Data!B8,2)))) -> 46242 | C8: =IFERROR(INDEX($T$10:$T$11,MATCH(PROPER(TRIM(Raw_Data!C8)),$S$10:$S$11,0)),PROPER(TRIM(Raw_Data!C8))) -> Koramangala | D8: =PROPER(TRIM(Raw_Data!D8)) -> Brownie | E8: =IFERROR(INDEX($T$6:$T$7,MATCH(PROPER(TRIM(Raw_Data!E8)),$S$6:$S$7,0)),PROPER(TRIM(Raw_Data!E8))) -> Bakery | F8: =IF(TRIM(Raw_Data!F8&"")="",1,VALUE(Raw_Data!F8)) -> 2 | G8: =VALUE(Raw_Data!G8) -> 150 | H8: =F8*G8 -> 300 | I8: =VALUE(Raw_Data!H8) -> 123 | J8: =H8-I8 -> 177 | K8: =IFERROR(J8/H8,0) -> 0.59 | L8: =TEXT(B8,"MMM-YYYY") -> Aug-2026 | M8: =YEAR(B8) -> 2026 | N8: =IF(TRIM(Raw_Data!I8&"")="","Not Specified",TRIM(Raw_Data!I8)) -> UPI | O8: =PROPER(TRIM(Raw_Data!J8)) -> Completed | P8: =IF(O8="Completed","Completed","Not Completed") -> Completed
A9: =Raw_Data!A9 -> ORD1046 | B9: =IF(ISNUMBER(Raw_Data!B9),Raw_Data!B9,DATE(VALUE(RIGHT(Raw_Data!B9,4)),VALUE(MID(Raw_Data!B9,4,2)),VALUE(LEFT(Raw_Data!B9,2)))) -> 46193 | C9: =IFERROR(INDEX($T$10:$T$11,MATCH(PROPER(TRIM(Raw_Data!C9)),$S$10:$S$11,0)),PROPER(TRIM(Raw_Data!C9))) -> Whitefield | D9: =PROPER(TRIM(Raw_Data!D9)) -> Hot Chocolate | E9: =IFERROR(INDEX($T$6:$T$7,MATCH(PROPER(TRIM(Raw_Data!E9)),$S$6:$S$7,0)),PROPER(TRIM(Raw_Data!E9))) -> Hot Beverages | F9: =IF(TRIM(Raw_Data!F9&"")="",1,VALUE(Raw_Data!F9)) -> 1 | G9: =VALUE(Raw_Data!G9) -> 170 | H9: =F9*G9 -> 170 | I9: =VALUE(Raw_Data!H9) -> 62 | J9: =H9-I9 -> 108 | K9: =IFERROR(J9/H9,0) -> 0.63529412 | L9: =TEXT(B9,"MMM-YYYY") -> Jun-2026 | M9: =YEAR(B9) -> 2026 | N9: =IF(TRIM(Raw_Data!I9&"")="","Not Specified",TRIM(Raw_Data!I9)) -> UPI | O9: =PROPER(TRIM(Raw_Data!J9)) -> Completed | P9: =IF(O9="Completed","Completed","Not Completed") -> Completed | S9: Outlet variant (after PROPER) | T9: Standardized to
A10: =Raw_Data!A10 -> ORD1007 | B10: =IF(ISNUMBER(Raw_Data!B10),Raw_Data!B10,DATE(VALUE(RIGHT(Raw_Data!B10,4)),VALUE(MID(Raw_Data!B10,4,2)),VALUE(LEFT(Raw_Data!B10,2)))) -> 46233 | C10: =IFERROR(INDEX($T$10:$T$11,MATCH(PROPER(TRIM(Raw_Data!C10)),$S$10:$S$11,0)),PROPER(TRIM(Raw_Data!C10))) -> HSR Layout | D10: =PROPER(TRIM(Raw_Data!D10)) -> Brownie | E10: =IFERROR(INDEX($T$6:$T$7,MATCH(PROPER(TRIM(Raw_Data!E10)),$S$6:$S$7,0)),PROPER(TRIM(Raw_Data!E10))) -> Bakery | F10: =IF(TRIM(Raw_Data!F10&"")="",1,VALUE(Raw_Data!F10)) -> 1 | G10: =VALUE(Raw_Data!G10) -> 150 | H10: =F10*G10 -> 150 | I10: =VALUE(Raw_Data!H10) -> 74 | J10: =H10-I10 -> 76 | K10: =IFERROR(J10/H10,0) -> 0.50666667 | L10: =TEXT(B10,"MMM-YYYY") -> Jul-2026 | M10: =YEAR(B10) -> 2026 | N10: =IF(TRIM(Raw_Data!I10&"")="","Not Specified",TRIM(Raw_Data!I10)) -> Cash | O10: =PROPER(TRIM(Raw_Data!J10)) -> Completed | P10: =IF(O10="Completed","Completed","Not Completed") -> Completed | S10: Hsr | T10: HSR Layout
A11: =Raw_Data!A11 -> ORD1053 | B11: =IF(ISNUMBER(Raw_Data!B11),Raw_Data!B11,DATE(VALUE(RIGHT(Raw_Data!B11,4)),VALUE(MID(Raw_Data!B11,4,2)),VALUE(LEFT(Raw_Data!B11,2)))) -> 46262 | C11: =IFERROR(INDEX($T$10:$T$11,MATCH(PROPER(TRIM(Raw_Data!C11)),$S$10:$S$11,0)),PROPER(TRIM(Raw_Data!C11))) -> Indiranagar | D11: =PROPER(TRIM(Raw_Data!D11)) -> Sandwich | E11: =IFERROR(INDEX($T$6:$T$7,MATCH(PROPER(TRIM(Raw_Data!E11)),$S$6:$S$7,0)),PROPER(TRIM(Raw_Data!E11))) -> Snacks | F11: =IF(TRIM(Raw_Data!F11&"")="",1,VALUE(Raw_Data!F11)) -> 3 | G11: =VALUE(Raw_Data!G11) -> 190 | H11: =F11*G11 -> 570 | I11: =VALUE(Raw_Data!H11) -> 259 | J11: =H11-I11 -> 311 | K11: =IFERROR(J11/H11,0) -> 0.54561404 | L11: =TEXT(B11,"MMM-YYYY") -> Aug-2026 | M11: =YEAR(B11) -> 2026 | N11: =IF(TRIM(Raw_Data!I11&"")="","Not Specified",TRIM(Raw_Data!I11)) -> UPI | O11: =PROPER(TRIM(Raw_Data!J11)) -> Completed | P11: =IF(O11="Completed","Completed","Not Completed") -> Completed | S11: Hsr Layout | T11: HSR Layout
A12: =Raw_Data!A12 -> ORD1092 | B12: =IF(ISNUMBER(Raw_Data!B12),Raw_Data!B12,DATE(VALUE(RIGHT(Raw_Data!B12,4)),VALUE(MID(Raw_Data!B12,4,2)),VALUE(LEFT(Raw_Data!B12,2)))) -> 46204 | C12: =IFERROR(INDEX($T$10:$T$11,MATCH(PROPER(TRIM(Raw_Data!C12)),$S$10:$S$11,0)),PROPER(TRIM(Raw_Data!C12))) -> Whitefield | D12: =PROPER(TRIM(Raw_Data!D12)) -> Garlic Bread | E12: =IFERROR(INDEX($T$6:$T$7,MATCH(PROPER(TRIM(Raw_Data!E12)),$S$6:$S$7,0)),PROPER(TRIM(Raw_Data!E12))) -> Snacks | F12: =IF(TRIM(Raw_Data!F12&"")="",1,VALUE(Raw_Data!F12)) -> 2 | G12: =VALUE(Raw_Data!G12) -> 150 | H12: =F12*G12 -> 300 | I12: =VALUE(Raw_Data!H12) -> 141 | J12: =H12-I12 -> 159 | K12: =IFERROR(J12/H12,0) -> 0.53 | L12: =TEXT(B12,"MMM-YYYY") -> Jul-2026 | M12: =YEAR(B12) -> 2026 | N12: =IF(TRIM(Raw_Data!I12&"")="","Not Specified",TRIM(Raw_Data!I12)) -> UPI | O12: =PROPER(TRIM(Raw_Data!J12)) -> Completed | P12: =IF(O12="Completed","Completed","Not Completed") -> Completed
A13: =Raw_Data!A13 -> ORD1130 | B13: =IF(ISNUMBER(Raw_Data!B13),Raw_Data!B13,DATE(VALUE(RIGHT(Raw_Data!B13,4)),VALUE(MID(Raw_Data!B13,4,2)),VALUE(LEFT(Raw_Data!B13,2)))) -> 46198 | C13: =IFERROR(INDEX($T$10:$T$11,MATCH(PROPER(TRIM(Raw_Data!C13)),$S$10:$S$11,0)),PROPER(TRIM(Raw_Data!C13))) -> Whitefield | D13: =PROPER(TRIM(Raw_Data!D13)) -> Espresso | E13: =IFERROR(INDEX($T$6:$T$7,MATCH(PROPER(TRIM(Raw_Data!E13)),$S$6:$S$7,0)),PROPER(TRIM(Raw_Data!E13))) -> Hot Beverages | F13: =IF(TRIM(Raw_Data!F13&"")="",1,VALUE(Raw_Data!F13)) -> 1 | G13: =VALUE(Raw_Data!G13) -> 150 | H13: =F13*G13 -> 150 | I13: =VALUE(Raw_Data!H13) -> 67 | J13: =H13-I13 -> 83 | K13: =IFERROR(J13/H13,0) -> 0.55333333 | L13: =TEXT(B13,"MMM-YYYY") -> Jun-2026 | M13: =YEAR(B13) -> 2026 | N13: =IF(TRIM(Raw_Data!I13&"")="","Not Specified",TRIM(Raw_Data!I13)) -> UPI | O13: =PROPER(TRIM(Raw_Data!J13)) -> Completed | P13: =IF(O13="Completed","Completed","Not Completed") -> Completed
A14: =Raw_Data!A14 -> ORD1184 | B14: =IF(ISNUMBER(Raw_Data!B14),Raw_Data!B14,DATE(VALUE(RIGHT(Raw_Data!B14,4)),VALUE(MID(Raw_Data!B14,4,2)),VALUE(LEFT(Raw_Data!B14,2)))) -> 46255 | C14: =IFERROR(INDEX($T$10:$T$11,MATCH(PROPER(TRIM(Raw_Data!C14)),$S$10:$S$11,0)),PROPER(TRIM(Raw_Data!C14))) -> Koramangala | D14: =PROPER(TRIM(Raw_Data!D14)) -> Croissant | E14: =IFERROR(INDEX($T$6:$T$7,MATCH(PROPER(TRIM(Raw_Data!E14)),$S$6:$S$7,0)),PROPER(TRIM(Raw_Data!E14))) -> Bakery | F14: =IF(TRIM(Raw_Data!F14&"")="",1,VALUE(Raw_Data!F14)) -> 2 | G14: =VALUE(Raw_Data!G14) -> 140 | H14: =F14*G14 -> 280 | I14: =VALUE(Raw_Data!H14) -> 116 | J14: =H14-I14 -> 164 | K14: =IFERROR(J14/H14,0) -> 0.58571429 | L14: =TEXT(B14,"MMM-YYYY") -> Aug-2026 | M14: =YEAR(B14) -> 2026 | N14: =IF(TRIM(Raw_Data!I14&"")="","Not Specified",TRIM(Raw_Data!I14)) -> Not Specified | O14: =PROPER(TRIM(Raw_Data!J14)) -> Completed | P14: =IF(O14="Completed","Completed","Not Completed") -> Completed
A15: =Raw_Data!A15 -> ORD1022 | B15: =IF(ISNUMBER(Raw_Data!B15),Raw_Data!B15,DATE(VALUE(RIGHT(Raw_Data!B15,4)),VALUE(MID(Raw_Data!B15,4,2)),VALUE(LEFT(Raw_Data!B15,2)))) -> 46255 | C15: =IFERROR(INDEX($T$10:$T$11,MATCH(PROPER(TRIM(Raw_Data!C15)),$S$10:$S$11,0)),PROPER(TRIM(Raw_Data!C15))) -> Whitefield | D15: =PROPER(TRIM(Raw_Data!D15)) -> Brownie | E15: =IFERROR(INDEX($T$6:$T$7,MATCH(PROPER(TRIM(Raw_Data!E15)),$S$6:$S$7,0)),PROPER(TRIM(Raw_Data!E15))) -> Bakery | F15: =IF(TRIM(Raw_Data!F15&"")="",1,VALUE(Raw_Data!F15)) -> 2 | G15: =VALUE(Raw_Data!G15) -> 150 | H15: =F15*G15 -> 300 | I15: =VALUE(Raw_Data!H15) -> 137 | J15: =H15-I15 -> 163 | K15: =IFERROR(J15/H15,0) -> 0.54333333 | L15: =TEXT(B15,"MMM-YYYY") -> Aug-2026 | M15: =YEAR(B15) -> 2026 | N15: =IF(TRIM(Raw_Data!I15&"")="","Not Specified",TRIM(Raw_Data!I15)) -> UPI | O15: =PROPER(TRIM(Raw_Data!J15)) -> Completed | P15: =IF(O15="Completed","Completed","Not Completed") -> Completed
A16: =Raw_Data!A16 -> ORD1043 | B16: =IF(ISNUMBER(Raw_Data!B16),Raw_Data!B16,DATE(VALUE(RIGHT(Raw_Data!B16,4)),VALUE(MID(Raw_Data!B16,4,2)),VALUE(LEFT(Raw_Data!B16,2)))) -> 46238 | C16: =IFERROR(INDEX($T$10:$T$11,MATCH(PROPER(TRIM(Raw_Data!C16)),$S$10:$S$11,0)),PROPER(TRIM(Raw_Data!C16))) -> Indiranagar | D16: =PROPER(TRIM(Raw_Data!D16)) -> Iced Tea | E16: =IFERROR(INDEX($T$6:$T$7,MATCH(PROPER(TRIM(Raw_Data!E16)),$S$6:$S$7,0)),PROPER(TRIM(Raw_Data!E16))) -> Cold Beverages | F16: =IF(TRIM(Raw_Data!F16&"")="",1,VALUE(Raw_Data!F16)) -> 2 | G16: =VALUE(Raw_Data!G16) -> 150 | H16: =F16*G16 -> 300 | I16: =VALUE(Raw_Data!H16) -> 130 | J16: =H16-I16 -> 170 | K16: =IFERROR(J16/H16,0) -> 0.56666667 | L16: =TEXT(B16,"MMM-YYYY") -> Aug-2026 | M16: =YEAR(B16) -> 2026 | N16: =IF(TRIM(Raw_Data!I16&"")="","Not Specified",TRIM(Raw_Data!I16)) -> UPI | O16: =PROPER(TRIM(Raw_Data!J16)) -> Cancelled | P16: =IF(O16="Completed","Completed","Not Completed") -> Not Completed
A17: =Raw_Data!A17 -> ORD1106 | B17: =IF(ISNUMBER(Raw_Data!B17),Raw_Data!B17,DATE(VALUE(RIGHT(Raw_Data!B17,4)),VALUE(MID(Raw_Data!B17,4,2)),VALUE(LEFT(Raw_Data!B17,2)))) -> 46213 | C17: =IFERROR(INDEX($T$10:$T$11,MATCH(PROPER(TRIM(Raw_Data!C17)),$S$10:$S$11,0)),PROPER(TRIM(Raw_Data!C17))) -> Koramangala | D17: =PROPER(TRIM(Raw_Data!D17)) -> Cappuccino | E17: =IFERROR(INDEX($T$6:$T$7,MATCH(PROPER(TRIM(Raw_Data!E17)),$S$6:$S$7,0)),PROPER(TRIM(Raw_Data!E17))) -> Hot Beverages | F17: =IF(TRIM(Raw_Data!F17&"")="",1,VALUE(Raw_Data!F17)) -> 1 | G17: =VALUE(Raw_Data!G17) -> 180 | H17: =F17*G17 -> 180 | I17: =VALUE(Raw_Data!H17) -> 79 | J17: =H17-I17 -> 101 | K17: =IFERROR(J17/H17,0) -> 0.56111111 | L17: =TEXT(B17,"MMM-YYYY") -> Jul-2026 | M17: =YEAR(B17) -> 2026 | N17: =IF(TRIM(Raw_Data!I17&"")="","Not Specified",TRIM(Raw_Data!I17)) -> Cash | O17: =PROPER(TRIM(Raw_Data!J17)) -> Completed | P17: =IF(O17="Completed","Completed","Not Completed") -> Completed
A18: =Raw_Data!A18 -> ORD1146 | B18: =IF(ISNUMBER(Raw_Data!B18),Raw_Data!B18,DATE(VALUE(RIGHT(Raw_Data!B18,4)),VALUE(MID(Raw_Data!B18,4,2)),VALUE(LEFT(Raw_Data!B18,2)))) -> 46255 | C18: =IFERROR(INDEX($T$10:$T$11,MATCH(PROPER(TRIM(Raw_Data!C18)),$S$10:$S$11,0)),PROPER(TRIM(Raw_Data!C18))) -> Indiranagar | D18: =PROPER(TRIM(Raw_Data!D18)) -> Danish Pastry | E18: =IFERROR(INDEX($T$6:$T$7,MATCH(PROPER(TRIM(Raw_Data!E18)),$S$6:$S$7,0)),PROPER(TRIM(Raw_Data!E18))) -> Bakery | F18: =IF(TRIM(Raw_Data!F18&"")="",1,VALUE(Raw_Data!F18)) -> 2 | G18: =VALUE(Raw_Data!G18) -> 160 | H18: =F18*G18 -> 320 | I18: =VALUE(Raw_Data!H18) -> 136 | J18: =H18-I18 -> 184 | K18: =IFERROR(J18/H18,0) -> 0.575 | L18: =TEXT(B18,"MMM-YYYY") -> Aug-2026 | M18: =YEAR(B18) -> 2026 | N18: =IF(TRIM(Raw_Data!I18&"")="","Not Specified",TRIM(Raw_Data!I18)) -> UPI | O18: =PROPER(TRIM(Raw_Data!J18)) -> Completed | P18: =IF(O18="Completed","Completed","Not Completed") -> Completed
A19: =Raw_Data!A19 -> ORD1088 | B19: =IF(ISNUMBER(Raw_Data!B19),Raw_Data!B19,DATE(VALUE(RIGHT(Raw_Data!B19,4)),VALUE(MID(Raw_Data!B19,4,2)),VALUE(LEFT(Raw_Data!B19,2)))) -> 46221 | C19: =IFERROR(INDEX($T$10:$T$11,MATCH(PROPER(TRIM(Raw_Data!C19)),$S$10:$S$11,0)),PROPER(TRIM(Raw_Data!C19))) -> HSR Layout | D19: =PROPER(TRIM(Raw_Data!D19)) -> Cappuccino | E19: =IFERROR(INDEX($T$6:$T$7,MATCH(PROPER(TRIM(Raw_Data!E19)),$S$6:$S$7,0)),PROPER(TRIM(Raw_Data!E19))) -> Hot Beverages | F19: =IF(TRIM(Raw_Data!F19&"")="",1,VALUE(Raw_Data!F19)) -> 3 | G19: =VALUE(Raw_Data!G19) -> 180 | H19: =F19*G19 -> 540 | I19: =VALUE(Raw_Data!H19) -> 223 | J19: =H19-I19 -> 317 | K19: =IFERROR(J19/H19,0) -> 0.58703704 | L19: =TEXT(B19,"MMM-YYYY") -> Jul-2026 | M19: =YEAR(B19) -> 2026 | N19: =IF(TRIM(Raw_Data!I19&"")="","Not Specified",TRIM(Raw_Data!I19)) -> Card | O19: =PROPER(TRIM(Raw_Data!J19)) -> Cancelled | P19: =IF(O19="Completed","Completed","Not Completed") -> Not Completed
A20: =Raw_Data!A20 -> ORD1153 | B20: =IF(ISNUMBER(Raw_Data!B20),Raw_Data!B20,DATE(VALUE(RIGHT(Raw_Data!B20,4)),VALUE(MID(Raw_Data!B20,4,2)),VALUE(LEFT(Raw_Data!B20,2)))) -> 46214 | C20: =IFERROR(INDEX($T$10:$T$11,MATCH(PROPER(TRIM(Raw_Data!C20)),$S$10:$S$11,0)),PROPER(TRIM(Raw_Data!C20))) -> Koramangala | D20: =PROPER(TRIM(Raw_Data!D20)) -> Latte | E20: =IFERROR(INDEX($T$6:$T$7,MATCH(PROPER(TRIM(Raw_Data!E20)),$S$6:$S$7,0)),PROPER(TRIM(Raw_Data!E20))) -> Hot Beverages | F20: =IF(TRIM(Raw_Data!F20&"")="",1,VALUE(Raw_Data!F20)) -> 2 | G20: =VALUE(Raw_Data!G20) -> 190 | H20: =F20*G20 -> 380 | I20: =VALUE(Raw_Data!H20) -> 167 | J20: =H20-I20 -> 213 | K20: =IFERROR(J20/H20,0) -> 0.56052632 | L20: =TEXT(B20,"MMM-YYYY") -> Jul-2026 | M20: =YEAR(B20) -> 2026 | N20: =IF(TRIM(Raw_Data!I20&"")="","Not Specified",TRIM(Raw_Data!I20)) -> Cash | O20: =PROPER(TRIM(Raw_Data!J20)) -> Completed | P20: =IF(O20="Completed","Completed","Not Completed") -> Completed
A21: =Raw_Data!A21 -> ORD1125 | B21: =IF(ISNUMBER(Raw_Data!B21),Raw_Data!B21,DATE(VALUE(RIGHT(Raw_Data!B21,4)),VALUE(MID(Raw_Data!B21,4,2)),VALUE(LEFT(Raw_Data!B21,2)))) -> 46244 | C21: =IFERROR(INDEX($T$10:$T$11,MATCH(PROPER(TRIM(Raw_Data!C21)),$S$10:$S$11,0)),PROPER(TRIM(Raw_Data!C21))) -> Whitefield | D21: =PROPER(TRIM(Raw_Data!D21)) -> Cold Brew | E21: =IFERROR(INDEX($T$6:$T$7,MATCH(PROPER(TRIM(Raw_Data!E21)),$S$6:$S$7,0)),PROPER(TRIM(Raw_Data!E21))) -> Cold Beverages | F21: =IF(TRIM(Raw_Data!F21&"")="",1,VALUE(Raw_Data!F21)) -> 4 | G21: =VALUE(Raw_Data!G21) -> 220 | H21: =F21*G21 -> 880 | I21: =VALUE(Raw_Data!H21) -> 412 | J21: =H21-I21 -> 468 | K21: =IFERROR(J21/H21,0) -> 0.53181818 | L21: =TEXT(B21,"MMM-YYYY") -> Aug-2026 | M21: =YEAR(B21) -> 2026 | N21: =IF(TRIM(Raw_Data!I21&"")="","Not Specified",TRIM(Raw_Data!I21)) -> Card | O21: =PROPER(TRIM(Raw_Data!J21)) -> Completed | P21: =IF(O21="Completed","Completed","Not Completed") -> Completed
A22: =Raw_Data!A22 -> ORD1093 | B22: =IF(ISNUMBER(Raw_Data!B22),Raw_Data!B22,DATE(VALUE(RIGHT(Raw_Data!B22,4)),VALUE(MID(Raw_Data!B22,4,2)),VALUE(LEFT(Raw_Data!B22,2)))) -> 46200 | C22: =IFERROR(INDEX($T$10:$T$11,MATCH(PROPER(TRIM(Raw_Data!C22)),$S$10:$S$11,0)),PROPER(TRIM(Raw_Data!C22))) -> HSR Layout | D22: =PROPER(TRIM(Raw_Data!D22)) -> Frappe | E22: =IFERROR(INDEX($T$6:$T$7,MATCH(PROPER(TRIM(Raw_Data!E22)),$S$6:$S$7,0)),PROPER(TRIM(Raw_Data!E22))) -> Cold Beverages | F22: =IF(TRIM(Raw_Data!F22&"")="",1,VALUE(Raw_Data!F22)) -> 2 | G22: =VALUE(Raw_Data!G22) -> 240 | H22: =F22*G22 -> 480 | I22: =VALUE(Raw_Data!H22) -> 198 | J22: =H22-I22 -> 282 | K22: =IFERROR(J22/H22,0) -> 0.5875 | L22: =TEXT(B22,"MMM-YYYY") -> Jun-2026 | M22: =YEAR(B22) -> 2026 | N22: =IF(TRIM(Raw_Data!I22&"")="","Not Specified",TRIM(Raw_Data!I22)) -> Cash | O22: =PROPER(TRIM(Raw_Data!J22)) -> Completed | P22: =IF(O22="Completed","Completed","Not Completed") -> Completed
A23: =Raw_Data!A23 -> ORD1102 | B23: =IF(ISNUMBER(Raw_Data!B23),Raw_Data!B23,DATE(VALUE(RIGHT(Raw_Data!B23,4)),VALUE(MID(Raw_Data!B23,4,2)),VALUE(LEFT(Raw_Data!B23,2)))) -> 46178 | C23: =IFERROR(INDEX($T$10:$T$11,MATCH(PROPER(TRIM(Raw_Data!C23)),$S$10:$S$11,0)),PROPER(TRIM(Raw_Data!C23))) -> Whitefield | D23: =PROPER(TRIM(Raw_Data!D23)) -> Hot Chocolate | E23: =IFERROR(INDEX($T$6:$T$7,MATCH(PROPER(TRIM(Raw_Data!E23)),$S$6:$S$7,0)),PROPER(TRIM(Raw_Data!E23))) -> Hot Beverages | F23: =IF(TRIM(Raw_Data!F23&"")="",1,VALUE(Raw_Data!F23)) -> 2 | G23: =VALUE(Raw_Data!G23) -> 170 | H23: =F23*G23 -> 340 | I23: =VALUE(Raw_Data!H23) -> 137 | J23: =H23-I23 -> 203 | K23: =IFERROR(J23/H23,0) -> 0.59705882 | L23: =TEXT(B23,"MMM-YYYY") -> Jun-2026 | M23: =YEAR(B23) -> 2026 | N23: =IF(TRIM(Raw_Data!I23&"")="","Not Specified",TRIM(Raw_Data!I23)) -> UPI | O23: =PROPER(TRIM(Raw_Data!J23)) -> Completed | P23: =IF(O23="Completed","Completed","Not Completed") -> Completed
... A36: =Raw_Data!A36 -> ORD1144 | B36: =IF(ISNUMBER(Raw_Data!B36),Raw_Data!B36,DATE(VALUE(RIGHT(Raw_Data!B36,4)),VALUE(MID(Raw_Data!B36,4,2)),VALUE(LEFT(Raw_Data!B36,2)))) -> 46223 | C36: =IFERROR(INDEX($T$10:$T$11,MATCH(PROPER(TRIM(Raw_Data!C36)),$S$10:$S$11,0)),PROPER(TRIM(Raw_Data!C36))) -> HSR Layout | D36: =PROPER(TRIM(Raw_Data!D36)) -> Iced Latte | E36: =IFERROR(INDEX($T$6:$T$7,MATCH(PROPER(TRIM(Raw_Data!E36)),$S$6:$S$7,0)),PROPER(TRIM(Raw_Data!E36))) -> Cold Beverages | F36: =IF(TRIM(Raw_Data!F36&"")="",1,VALUE(Raw_Data!F36)) -> 1 | G36: =VALUE(Raw_Data!G36) -> 200 | H36: =F36*G36 -> 200 | I36: =VALUE(Raw_Data!H36) -> 93 | J36: =H36-I36 -> 107 | K36: =IFERROR(J36/H36,0) -> 0.535 | L36: =TEXT(B36,"MMM-YYYY") -> Jul-2026 | M36: =YEAR(B36) -> 2026 | N36: =IF(TRIM(Raw_Data!I36&"")="","Not Specified",TRIM(Raw_Data!I36)) -> UPI | O36: =PROPER(TRIM(Raw_Data!J36)) -> Cancelled | P36: =IF(O36="Completed","Completed","Not Completed") -> Not Completed
A37: =Raw_Data!A38 -> ORD1023 | B37: =IF(ISNUMBER(Raw_Data!B38),Raw_Data!B38,DATE(VALUE(RIGHT(Raw_Data!B38,4)),VALUE(MID(Raw_Data!B38,4,2)),VALUE(LEFT(Raw_Data!B38,2)))) -> 46233 | C37: =IFERROR(INDEX($T$10:$T$11,MATCH(PROPER(TRIM(Raw_Data!C38)),$S$10:$S$11,0)),PROPER(TRIM(Raw_Data!C38))) -> HSR Layout | D37: =PROPER(TRIM(Raw_Data!D38)) -> Garlic Bread | E37: =IFERROR(INDEX($T$6:$T$7,MATCH(PROPER(TRIM(Raw_Data!E38)),$S$6:$S$7,0)),PROPER(TRIM(Raw_Data!E38))) -> Snacks | F37: =IF(TRIM(Raw_Data!F38&"")="",1,VALUE(Raw_Data!F38)) -> 1 | G37: =VALUE(Raw_Data!G38) -> 150 | H37: =F37*G37 -> 150 | I37: =VALUE(Raw_Data!H38) -> 66 | J37: =H37-I37 -> 84 | K37: =IFERROR(J37/H37,0) -> 0.56 | L37: =TEXT(B37,"MMM-YYYY") -> Jul-2026 | M37: =YEAR(B37) -> 2026 | N37: =IF(TRIM(Raw_Data!I38&"")="","Not Specified",TRIM(Raw_Data!I38)) -> Cash | O37: =PROPER(TRIM(Raw_Data!J38)) -> Completed | P37: =IF(O37="Completed","Completed","Not Completed") -> Completed
A38: =Raw_Data!A39 -> ORD1103 | B38: =IF(ISNUMBER(Raw_Data!B39),Raw_Data!B39,DATE(VALUE(RIGHT(Raw_Data!B39,4)),VALUE(MID(Raw_Data!B39,4,2)),VALUE(LEFT(Raw_Data!B39,2)))) -> 46186 | C38: =IFERROR(INDEX($T$10:$T$11,MATCH(PROPER(TRIM(Raw_Data!C39)),$S$10:$S$11,0)),PROPER(TRIM(Raw_Data!C39))) -> Koramangala | D38: =PROPER(TRIM(Raw_Data!D39)) -> Croissant | E38: =IFERROR(INDEX($T$6:$T$7,MATCH(PROPER(TRIM(Raw_Data!E39)),$S$6:$S$7,0)),PROPER(TRIM(Raw_Data!E39))) -> Bakery | F38: =IF(TRIM(Raw_Data!F39&"")="",1,VALUE(Raw_Data!F39)) -> 2 | G38: =VALUE(Raw_Data!G39) -> 140 | H38: =F38*G38 -> 280 | I38: =VALUE(Raw_Data!H39) -> 132 | J38: =H38-I38 -> 148 | K38: =IFERROR(J38/H38,0) -> 0.52857143 | L38: =TEXT(B38,"MMM-YYYY") -> Jun-2026 | M38: =YEAR(B38) -> 2026 | N38: =IF(TRIM(Raw_Data!I39&"")="","Not Specified",TRIM(Raw_Data!I39)) -> UPI | O38: =PROPER(TRIM(Raw_Data!J39)) -> Completed | P38: =IF(O38="Completed","Completed","Not Completed") -> Completed
A39: =Raw_Data!A40 -> ORD1061 | B39: =IF(ISNUMBER(Raw_Data!B40),Raw_Data!B40,DATE(VALUE(RIGHT(Raw_Data!B40,4)),VALUE(MID(Raw_Data!B40,4,2)),VALUE(LEFT(Raw_Data!B40,2)))) -> 46255 | C39: =IFERROR(INDEX($T$10:$T$11,MATCH(PROPER(TRIM(Raw_Data!C40)),$S$10:$S$11,0)),PROPER(TRIM(Raw_Data!C40))) -> Indiranagar | D39: =PROPER(TRIM(Raw_Data!D40)) -> Danish Pastry | E39: =IFERROR(INDEX($T$6:$T$7,MATCH(PROPER(TRIM(Raw_Data!E40)),$S$6:$S$7,0)),PROPER(TRIM(Raw_Data!E40))) -> Bakery | F39: =IF(TRIM(Raw_Data!F40&"")="",1,VALUE(Raw_Data!F40)) -> 4 | G39: =VALUE(Raw_Data!G40) -> 160 | H39: =F39*G39 -> 640 | I39: =VALUE(Raw_Data!H40) -> 331 | J39: =H39-I39 -> 309 | K39: =IFERROR(J39/H39,0) -> 0.4828125 | L39: =TEXT(B39,"MMM-YYYY") -> Aug-2026 | M39: =YEAR(B39) -> 2026 | N39: =IF(TRIM(Raw_Data!I40&"")="","Not Specified",TRIM(Raw_Data!I40)) -> Card | O39: =PROPER(TRIM(Raw_Data!J40)) -> Completed | P39: =IF(O39="Completed","Completed","Not Completed") -> Completed
A40: =Raw_Data!A41 -> ORD1137 | B40: =IF(ISNUMBER(Raw_Data!B41),Raw_Data!B41,DATE(VALUE(RIGHT(Raw_Data!B41,4)),VALUE(MID(Raw_Data!B41,4,2)),VALUE(LEFT(Raw_Data!B41,2)))) -> 46178 | C40: =IFERROR(INDEX($T$10:$T$11,MATCH(PROPER(TRIM(Raw_Data!C41)),$S$10:$S$11,0)),PROPER(TRIM(Raw_Data!C41))) -> HSR Layout | D40: =PROPER(TRIM(Raw_Data!D41)) -> Garlic Bread | E40: =IFERROR(INDEX($T$6:$T$7,MATCH(PROPER(TRIM(Raw_Data!E41)),$S$6:$S$7,0)),PROPER(TRIM(Raw_Data!E41))) -> Snacks | F40: =IF(TRIM(Raw_Data!F41&"")="",1,VALUE(Raw_Data!F41)) -> 1 | G40: =VALUE(Raw_Data!G41) -> 150 | H40: =F40*G40 -> 150 | I40: =VALUE(Raw_Data!H41) -> 65 | J40: =H40-I40 -> 85 | K40: =IFERROR(J40/H40,0) -> 0.56666667 | L40: =TEXT(B40,"MMM-YYYY") -> Jun-2026 | M40: =YEAR(B40) -> 2026 | N40: =IF(TRIM(Raw_Data!I41&"")="","Not Specified",TRIM(Raw_Data!I41)) -> UPI | O40: =PROPER(TRIM(Raw_Data!J41)) -> Completed | P40: =IF(O40="Completed","Completed","Not Completed") -> Completed
A41: =Raw_Data!A42 -> ORD1169 | B41: =IF(ISNUMBER(Raw_Data!B42),Raw_Data!B42,DATE(VALUE(RIGHT(Raw_Data!B42,4)),VALUE(MID(Raw_Data!B42,4,2)),VALUE(LEFT(Raw_Data!B42,2)))) -> 46174 | C41: =IFERROR(INDEX($T$10:$T$11,MATCH(PROPER(TRIM(Raw_Data!C42)),$S$10:$S$11,0)),PROPER(TRIM(Raw_Data!C42))) -> Koramangala | D41: =PROPER(TRIM(Raw_Data!D42)) -> Latte | E41: =IFERROR(INDEX($T$6:$T$7,MATCH(PROPER(TRIM(Raw_Data!E42)),$S$6:$S$7,0)),PROPER(TRIM(Raw_Data!E42))) -> Hot Beverages | F41: =IF(TRIM(Raw_Data!F42&"")="",1,VALUE(Raw_Data!F42)) -> 2 | G41: =VALUE(Raw_Data!G42) -> 190 | H41: =F41*G41 -> 380 | I41: =VALUE(Raw_Data!H42) -> 148 | J41: =H41-I41 -> 232 | K41: =IFERROR(J41/H41,0) -> 0.61052632 | L41: =TEXT(B41,"MMM-YYYY") -> Jun-2026 | M41: =YEAR(B41) -> 2026 | N41: =IF(TRIM(Raw_Data!I42&"")="","Not Specified",TRIM(Raw_Data!I42)) -> UPI | O41: =PROPER(TRIM(Raw_Data!J42)) -> Completed | P41: =IF(O41="Completed","Completed","Not Completed") -> Completed
A42: =Raw_Data!A43 -> ORD1139 | B42: =IF(ISNUMBER(Raw_Data!B43),Raw_Data!B43,DATE(VALUE(RIGHT(Raw_Data!B43,4)),VALUE(MID(Raw_Data!B43,4,2)),VALUE(LEFT(Raw_Data!B43,2)))) -> 46227 | C42: =IFERROR(INDEX($T$10:$T$11,MATCH(PROPER(TRIM(Raw_Data!C43)),$S$10:$S$11,0)),PROPER(TRIM(Raw_Data!C43))) -> Koramangala | D42: =PROPER(TRIM(Raw_Data!D43)) -> Croissant | E42: =IFERROR(INDEX($T$6:$T$7,MATCH(PROPER(TRIM(Raw_Data!E43)),$S$6:$S$7,0)),PROPER(TRIM(Raw_Data!E43))) -> Bakery | F42: =IF(TRIM(Raw_Data!F43&"")="",1,VALUE(Raw_Data!F43)) -> 2 | G42: =VALUE(Raw_Data!G43) -> 140 | H42: =F42*G42 -> 280 | I42: =VALUE(Raw_Data!H43) -> 142 | J42: =H42-I42 -> 138 | K42: =IFERROR(J42/H42,0) -> 0.49285714 | L42: =TEXT(B42,"MMM-YYYY") -> Jul-2026 | M42: =YEAR(B42) -> 2026 | N42: =IF(TRIM(Raw_Data!I43&"")="","Not Specified",TRIM(Raw_Data!I43)) -> UPI | O42: =PROPER(TRIM(Raw_Data!J43)) -> Completed | P42: =IF(O42="Completed","Completed","Not Completed") -> Completed
A43: =Raw_Data!A44 -> ORD1055 | B43: =IF(ISNUMBER(Raw_Data!B44),Raw_Data!B44,DATE(VALUE(RIGHT(Raw_Data!B44,4)),VALUE(MID(Raw_Data!B44,4,2)),VALUE(LEFT(Raw_Data!B44,2)))) -> 46244 | C43: =IFERROR(INDEX($T$10:$T$11,MATCH(PROPER(TRIM(Raw_Data!C44)),$S$10:$S$11,0)),PROPER(TRIM(Raw_Data!C44))) -> HSR Layout | D43: =PROPER(TRIM(Raw_Data!D44)) -> Iced Tea | E43: =IFERROR(INDEX($T$6:$T$7,MATCH(PROPER(TRIM(Raw_Data!E44)),$S$6:$S$7,0)),PROPER(TRIM(Raw_Data!E44))) -> Cold Beverages | F43: =IF(TRIM(Raw_Data!F44&"")="",1,VALUE(Raw_Data!F44)) -> 2 | G43: =VALUE(Raw_Data!G44) -> 150 | H43: =F43*G43 -> 300 | I43: =VALUE(Raw_Data!H44) -> 115 | J43: =H43-I43 -> 185 | K43: =IFERROR(J43/H43,0) -> 0.61666667 | L43: =TEXT(B43,"MMM-YYYY") -> Aug-2026 | M43: =YEAR(B43) -> 2026 | N43: =IF(TRIM(Raw_Data!I44&"")="","Not Specified",TRIM(Raw_Data!I44)) -> Cash | O43: =PROPER(TRIM(Raw_Data!J44)) -> Cancelled | P43: =IF(O43="Completed","Completed","Not Completed") -> Not Completed
A44: =Raw_Data!A45 -> ORD1177 | B44: =IF(ISNUMBER(Raw_Data!B45),Raw_Data!B45,DATE(VALUE(RIGHT(Raw_Data!B45,4)),VALUE(MID(Raw_Data!B45,4,2)),VALUE(LEFT(Raw_Data!B45,2)))) -> 46215 | C44: =IFERROR(INDEX($T$10:$T$11,MATCH(PROPER(TRIM(Raw_Data!C45)),$S$10:$S$11,0)),PROPER(TRIM(Raw_Data!C45))) -> Indiranagar | D44: =PROPER(TRIM(Raw_Data!D45)) -> Danish Pastry | E44: =IFERROR(INDEX($T$6:$T$7,MATCH(PROPER(TRIM(Raw_Data!E45)),$S$6:$S$7,0)),PROPER(TRIM(Raw_Data!E45))) -> Bakery | F44: =IF(TRIM(Raw_Data!F45&"")="",1,VALUE(Raw_Data!F45)) -> 1 | G44: =VALUE(Raw_Data!G45) -> 160 | H44: =F44*G44 -> 160 | I44: =VALUE(Raw_Data!H45) -> 69 | J44: =H44-I44 -> 91 | K44: =IFERROR(J44/H44,0) -> 0.56875 | L44: =TEXT(B44,"MMM-YYYY") -> Jul-2026 | M44: =YEAR(B44) -> 2026 | N44: =IF(TRIM(Raw_Data!I45&"")="","Not Specified",TRIM(Raw_Data!I45)) -> Card | O44: =PROPER(TRIM(Raw_Data!J45)) -> Completed | P44: =IF(O44="Completed","Completed","Not Completed") -> Completed
A45: =Raw_Data!A46 -> ORD1112 | B45: =IF(ISNUMBER(Raw_Data!B46),Raw_Data!B46,DATE(VALUE(RIGHT(Raw_Data!B46,4)),VALUE(MID(Raw_Data!B46,4,2)),VALUE(LEFT(Raw_Data!B46,2)))) -> 46264 | C45: =IFERROR(INDEX($T$10:$T$11,MATCH(PROPER(TRIM(Raw_Data!C46)),$S$10:$S$11,0)),PROPER(TRIM(Raw_Data!C46))) -> Koramangala | D45: =PROPER(TRIM(Raw_Data!D46)) -> Cold Brew | E45: =IFERROR(INDEX($T$6:$T$7,MATCH(PROPER(TRIM(Raw_Data!E46)),$S$6:$S$7,0)),PROPER(TRIM(Raw_Data!E46))) -> Cold Beverages | F45: =IF(TRIM(Raw_Data!F46&"")="",1,VALUE(Raw_Data!F46)) -> 1 | G45: =VALUE(Raw_Data!G46) -> 220 | H45: =F45*G45 -> 220 | I45: =VALUE(Raw_Data!H46) -> 103 | J45: =H45-I45 -> 117 | K45: =IFERROR(J45/H45,0) -> 0.53181818 | L45: =TEXT(B45,"MMM-YYYY") -> Aug-2026 | M45: =YEAR(B45) -> 2026 | N45: =IF(TRIM(Raw_Data!I46&"")="","Not Specified",TRIM(Raw_Data!I46)) -> Card | O45: =PROPER(TRIM(Raw_Data!J46)) -> Completed | P45: =IF(O45="Completed","Completed","Not Completed") -> Completed
A46: =Raw_Data!A47 -> ORD1115 | B46: =IF(ISNUMBER(Raw_Data!B47),Raw_Data!B47,DATE(VALUE(RIGHT(Raw_Data!B47,4)),VALUE(MID(Raw_Data!B47,4,2)),VALUE(LEFT(Raw_Data!B47,2)))) -> 46184 | C46: =IFERROR(INDEX($T$10:$T$11,MATCH(PROPER(TRIM(Raw_Data!C47)),$S$10:$S$11,0)),PROPER(TRIM(Raw_Data!C47))) -> Whitefield | D46: =PROPER(TRIM(Raw_Data!D47)) -> Sandwich | E46: =IFERROR(INDEX($T$6:$T$7,MATCH(PROPER(TRIM(Raw_Data!E47)),$S$6:$S$7,0)),PROPER(TRIM(Raw_Data!E47))) -> Snacks | F46: =IF(TRIM(Raw_Data!F47&"")="",1,VALUE(Raw_Data!F47)) -> 4 | G46: =VALUE(Raw_Data!G47) -> 190 | H46: =F46*G46 -> 760 | I46: =VALUE(Raw_Data!H47) -> 331 | J46: =H46-I46 -> 429 | K46: =IFERROR(J46/H46,0) -> 0.56447368 | L46: =TEXT(B46,"MMM-YYYY") -> Jun-2026 | M46: =YEAR(B46) -> 2026 | N46: =IF(TRIM(Raw_Data!I47&"")="","Not Specified",TRIM(Raw_Data!I47)) -> Card | O46: =PROPER(TRIM(Raw_Data!J47)) -> Completed | P46: =IF(O46="Completed","Completed","Not Completed") -> Completed
A47: =Raw_Data!A48 -> ORD1015 | B47: =IF(ISNUMBER(Raw_Data!B48),Raw_Data!B48,DATE(VALUE(RIGHT(Raw_Data!B48,4)),VALUE(MID(Raw_Data!B48,4,2)),VALUE(LEFT(Raw_Data!B48,2)))) -> 46229 | C47: =IFERROR(INDEX($T$10:$T$11,MATCH(PROPER(TRIM(Raw_Data!C48)),$S$10:$S$11,0)),PROPER(TRIM(Raw_Data!C48))) -> Whitefield | D47: =PROPER(TRIM(Raw_Data!D48)) -> Sandwich | E47: =IFERROR(INDEX($T$6:$T$7,MATCH(PROPER(TRIM(Raw_Data!E48)),$S$6:$S$7,0)),PROPER(TRIM(Raw_Data!E48))) -> Snacks | F47: =IF(TRIM(Raw_Data!F48&"")="",1,VALUE(Raw_Data!F48)) -> 4 | G47: =VALUE(Raw_Data!G48) -> 190 | H47: =F47*G47 -> 760 | I47: =VALUE(Raw_Data!H48) -> 387 | J47: =H47-I47 -> 373 | K47: =IFERROR(J47/H47,0) -> 0.49078947 | L47: =TEXT(B47,"MMM-YYYY") -> Jul-2026 | M47: =YEAR(B47) -> 2026 | N47: =IF(TRIM(Raw_Data!I48&"")="","Not Specified",TRIM(Raw_Data!I48)) -> UPI | O47: =PROPER(TRIM(Raw_Data!J48)) -> Completed | P47: =IF(O47="Completed","Completed","Not Completed") -> Completed
A48: =Raw_Data!A49 -> ORD1107 | B48: =IF(ISNUMBER(Raw_Data!B49),Raw_Data!B49,DATE(VALUE(RIGHT(Raw_Data!B49,4)),VALUE(MID(Raw_Data!B49,4,2)),VALUE(LEFT(Raw_Data!B49,2)))) -> 46203 | C48: =IFERROR(INDEX($T$10:$T$11,MATCH(PROPER(TRIM(Raw_Data!C49)),$S$10:$S$11,0)),PROPER(TRIM(Raw_Data!C49))) -> HSR Layout | D48: =PROPER(TRIM(Raw_Data!D49)) -> Brownie | E48: =IFERROR(INDEX($T$6:$T$7,MATCH(PROPER(TRIM(Raw_Data!E49)),$S$6:$S$7,0)),PROPER(TRIM(Raw_Data!E49))) -> Bakery | F48: =IF(TRIM(Raw_Data!F49&"")="",1,VALUE(Raw_Data!F49)) -> 1 | G48: =VALUE(Raw_Data!G49) -> 150 | H48: =F48*G48 -> 150 | I48: =VALUE(Raw_Data!H49) -> 61 | J48: =H48-I48 -> 89 | K48: =IFERROR(J48/H48,0) -> 0.59333333 | L48: =TEXT(B48,"MMM-YYYY") -> Jun-2026 | M48: =YEAR(B48) -> 2026 | N48: =IF(TRIM(Raw_Data!I49&"")="","Not Specified",TRIM(Raw_Data!I49)) -> Not Specified | O48: =PROPER(TRIM(Raw_Data!J49)) -> Completed | P48: =IF(O48="Completed","Completed","Not Completed") -> Completed
... A78: =Raw_Data!A79 -> ORD1155 | B78: =IF(ISNUMBER(Raw_Data!B79),Raw_Data!B79,DATE(VALUE(RIGHT(Raw_Data!B79,4)),VALUE(MID(Raw_Data!B79,4,2)),VALUE(LEFT(Raw_Data!B79,2)))) -> 46195 | C78: =IFERROR(INDEX($T$10:$T$11,MATCH(PROPER(TRIM(Raw_Data!C79)),$S$10:$S$11,0)),PROPER(TRIM(Raw_Data!C79))) -> Indiranagar | D78: =PROPER(TRIM(Raw_Data!D79)) -> Espresso | E78: =IFERROR(INDEX($T$6:$T$7,MATCH(PROPER(TRIM(Raw_Data!E79)),$S$6:$S$7,0)),PROPER(TRIM(Raw_Data!E79))) -> Hot Beverages | F78: =IF(TRIM(Raw_Data!F79&"")="",1,VALUE(Raw_Data!F79)) -> 3 | G78: =VALUE(Raw_Data!G79) -> 150 | H78: =F78*G78 -> 450 | I78: =VALUE(Raw_Data!H79) -> 185 | J78: =H78-I78 -> 265 | K78: =IFERROR(J78/H78,0) -> 0.58888889 | L78: =TEXT(B78,"MMM-YYYY") -> Jun-2026 | M78: =YEAR(B78) -> 2026 | N78: =IF(TRIM(Raw_Data!I79&"")="","Not Specified",TRIM(Raw_Data!I79)) -> UPI | O78: =PROPER(TRIM(Raw_Data!J79)) -> Completed | P78: =IF(O78="Completed","Completed","Not Completed") -> Completed
A79: =Raw_Data!A81 -> ORD1001 | B79: =IF(ISNUMBER(Raw_Data!B81),Raw_Data!B81,DATE(VALUE(RIGHT(Raw_Data!B81,4)),VALUE(MID(Raw_Data!B81,4,2)),VALUE(LEFT(Raw_Data!B81,2)))) -> 46215 | C79: =IFERROR(INDEX($T$10:$T$11,MATCH(PROPER(TRIM(Raw_Data!C81)),$S$10:$S$11,0)),PROPER(TRIM(Raw_Data!C81))) -> Indiranagar | D79: =PROPER(TRIM(Raw_Data!D81)) -> Danish Pastry | E79: =IFERROR(INDEX($T$6:$T$7,MATCH(PROPER(TRIM(Raw_Data!E81)),$S$6:$S$7,0)),PROPER(TRIM(Raw_Data!E81))) -> Bakery | F79: =IF(TRIM(Raw_Data!F81&"")="",1,VALUE(Raw_Data!F81)) -> 2 | G79: =VALUE(Raw_Data!G81) -> 160 | H79: =F79*G79 -> 320 | I79: =VALUE(Raw_Data!H81) -> 131 | J79: =H79-I79 -> 189 | K79: =IFERROR(J79/H79,0) -> 0.590625 | L79: =TEXT(B79,"MMM-YYYY") -> Jul-2026 | M79: =YEAR(B79) -> 2026 | N79: =IF(TRIM(Raw_Data!I81&"")="","Not Specified",TRIM(Raw_Data!I81)) -> UPI | O79: =PROPER(TRIM(Raw_Data!J81)) -> Completed | P79: =IF(O79="Completed","Completed","Not Completed") -> Completed
A80: =Raw_Data!A82 -> ORD1171 | B80: =IF(ISNUMBER(Raw_Data!B82),Raw_Data!B82,DATE(VALUE(RIGHT(Raw_Data!B82,4)),VALUE(MID(Raw_Data!B82,4,2)),VALUE(LEFT(Raw_Data!B82,2)))) -> 46256 | C80: =IFERROR(INDEX($T$10:$T$11,MATCH(PROPER(TRIM(Raw_Data!C82)),$S$10:$S$11,0)),PROPER(TRIM(Raw_Data!C82))) -> HSR Layout | D80: =PROPER(TRIM(Raw_Data!D82)) -> Cold Brew | E80: =IFERROR(INDEX($T$6:$T$7,MATCH(PROPER(TRIM(Raw_Data!E82)),$S$6:$S$7,0)),PROPER(TRIM(Raw_Data!E82))) -> Cold Beverages | F80: =IF(TRIM(Raw_Data!F82&"")="",1,VALUE(Raw_Data!F82)) -> 2 | G80: =VALUE(Raw_Data!G82) -> 220 | H80: =F80*G80 -> 440 | I80: =VALUE(Raw_Data!H82) -> 170 | J80: =H80-I80 -> 270 | K80: =IFERROR(J80/H80,0) -> 0.61363636 | L80: =TEXT(B80,"MMM-YYYY") -> Aug-2026 | M80: =YEAR(B80) -> 2026 | N80: =IF(TRIM(Raw_Data!I82&"")="","Not Specified",TRIM(Raw_Data!I82)) -> Cash | O80: =PROPER(TRIM(Raw_Data!J82)) -> Cancelled | P80: =IF(O80="Completed","Completed","Not Completed") -> Not Completed
A81: =Raw_Data!A83 -> ORD1035 | B81: =IF(ISNUMBER(Raw_Data!B83),Raw_Data!B83,DATE(VALUE(RIGHT(Raw_Data!B83,4)),VALUE(MID(Raw_Data!B83,4,2)),VALUE(LEFT(Raw_Data!B83,2)))) -> 46258 | C81: =IFERROR(INDEX($T$10:$T$11,MATCH(PROPER(TRIM(Raw_Data!C83)),$S$10:$S$11,0)),PROPER(TRIM(Raw_Data!C83))) -> Whitefield | D81: =PROPER(TRIM(Raw_Data!D83)) -> Hot Chocolate | E81: =IFERROR(INDEX($T$6:$T$7,MATCH(PROPER(TRIM(Raw_Data!E83)),$S$6:$S$7,0)),PROPER(TRIM(Raw_Data!E83))) -> Hot Beverages | F81: =IF(TRIM(Raw_Data!F83&"")="",1,VALUE(Raw_Data!F83)) -> 2 | G81: =VALUE(Raw_Data!G83) -> 170 | H81: =F81*G81 -> 340 | I81: =VALUE(Raw_Data!H83) -> 123 | J81: =H81-I81 -> 217 | K81: =IFERROR(J81/H81,0) -> 0.63823529 | L81: =TEXT(B81,"MMM-YYYY") -> Aug-2026 | M81: =YEAR(B81) -> 2026 | N81: =IF(TRIM(Raw_Data!I83&"")="","Not Specified",TRIM(Raw_Data!I83)) -> UPI | O81: =PROPER(TRIM(Raw_Data!J83)) -> Cancelled | P81: =IF(O81="Completed","Completed","Not Completed") -> Not Completed
A82: =Raw_Data!A84 -> ORD1128 | B82: =IF(ISNUMBER(Raw_Data!B84),Raw_Data!B84,DATE(VALUE(RIGHT(Raw_Data!B84,4)),VALUE(MID(Raw_Data!B84,4,2)),VALUE(LEFT(Raw_Data!B84,2)))) -> 46259 | C82: =IFERROR(INDEX($T$10:$T$11,MATCH(PROPER(TRIM(Raw_Data!C84)),$S$10:$S$11,0)),PROPER(TRIM(Raw_Data!C84))) -> Koramangala | D82: =PROPER(TRIM(Raw_Data!D84)) -> Croissant | E82: =IFERROR(INDEX($T$6:$T$7,MATCH(PROPER(TRIM(Raw_Data!E84)),$S$6:$S$7,0)),PROPER(TRIM(Raw_Data!E84))) -> Bakery | F82: =IF(TRIM(Raw_Data!F84&"")="",1,VALUE(Raw_Data!F84)) -> 1 | G82: =VALUE(Raw_Data!G84) -> 140 | H82: =F82*G82 -> 140 | I82: =VALUE(Raw_Data!H84) -> 66 | J82: =H82-I82 -> 74 | K82: =IFERROR(J82/H82,0) -> 0.52857143 | L82: =TEXT(B82,"MMM-YYYY") -> Aug-2026 | M82: =YEAR(B82) -> 2026 | N82: =IF(TRIM(Raw_Data!I84&"")="","Not Specified",TRIM(Raw_Data!I84)) -> UPI | O82: =PROPER(TRIM(Raw_Data!J84)) -> Completed | P82: =IF(O82="Completed","Completed","Not Completed") -> Completed
...

Sheet Calculations
A1: Calculations — Core KPIs (formulas reference Cleaned_Data; nothing is a typed-in number)
A3: Revenue & Profit KPIs
A4: Total Orders | B4: =COUNTA(Cleaned_Data!$A$5:$A$201) -> 197
A5: Completed Orders | B5: =COUNTIF(Cleaned_Data!$O$5:$O$201,"Completed") -> 170
A6: Cancelled Orders | B6: =COUNTIF(Cleaned_Data!$O$5:$O$201,"Cancelled") -> 27
A7: Completed Orders % | B7: =B5/B4 -> 0.86294416
A8: Cancelled Orders % | B8: =B6/B4 -> 0.13705584
A9: Total Sales (Completed only) | B9: =SUMIFS(Cleaned_Data!$H$5:$H$201,Cleaned_Data!$O$5:$O$201,"Completed") -> 47560
A10: Total Cost (Completed only) | B10: =SUMIFS(Cleaned_Data!$I$5:$I$201,Cleaned_Data!$O$5:$O$201,"Completed") -> 20961
A11: Total Profit (Completed only) | B11: =B9-B10 -> 26599
A12: Profit Margin % | B12: =B11/B9 -> 0.5592725
A13: Average Order Value | B13: =B9/B5 -> 279.76471
A16: Monthly Trend & Growth
A17: Month | B17: Sales (Completed)
A18: Jun-2026 | B18: =SUMIFS(Cleaned_Data!$H$5:$H$201,Cleaned_Data!$L$5:$L$201,A18,Cleaned_Data!$O$5:$O$201,"Completed") -> 15900
A19: Jul-2026 | B19: =SUMIFS(Cleaned_Data!$H$5:$H$201,Cleaned_Data!$L$5:$L$201,A19,Cleaned_Data!$O$5:$O$201,"Completed") -> 12310
A20: Aug-2026 | B20: =SUMIFS(Cleaned_Data!$H$5:$H$201,Cleaned_Data!$L$5:$L$201,A20,Cleaned_Data!$O$5:$O$201,"Completed") -> 19350
A22: MoM Growth (Aug vs. Jul) | B22: =IFERROR((B20-B19)/B19,0) -> 0.57189277

Sheet PivotTables
A1: PivotTables — Summary views answering each business question (built with SUMIFS/COUNTIFS)
A2: Note: these are formula-driven summary tables rather than native Excel PivotTable objects, so every number recalculates instantly and the file has zero risk of a broken pivot cache. See the README tab for how to convert any of these into a real Insert > PivotTable in under a minute.
A4: 1. Sales by Month (Rows: Month | Values: Sum of Sales, Completed only)
A5: Month | B5: Sales
A6: Jun-2026 | B6: =SUMIFS(Cleaned_Data!$H$5:$H$201,Cleaned_Data!$L$5:$L$201,A6,Cleaned_Data!$O$5:$O$201,"Completed") -> 15900
A7: Jul-2026 | B7: =SUMIFS(Cleaned_Data!$H$5:$H$201,Cleaned_Data!$L$5:$L$201,A7,Cleaned_Data!$O$5:$O$201,"Completed") -> 12310
A8: Aug-2026 | B8: =SUMIFS(Cleaned_Data!$H$5:$H$201,Cleaned_Data!$L$5:$L$201,A8,Cleaned_Data!$O$5:$O$201,"Completed") -> 19350
A11: 2. Sales & Profit by Category (Rows: Category | Values: Sum of Sales, Profit, Margin %)
A12: Category | B12: Sales | C12: Profit | D12: Profit Margin % | E12: % of Total Sales
A13: Hot Beverages | B13: =SUMIFS(Cleaned_Data!$H$5:$H$201,Cleaned_Data!$E$5:$E$201,A13,Cleaned_Data!$O$5:$O$201,"Completed") -> 11960 | C13: =SUMIFS(Cleaned_Data!$J$5:$J$201,Cleaned_Data!$E$5:$E$201,A13,Cleaned_Data!$O$5:$O$201,"Completed") -> 7131 | D13: =IFERROR(C13/B13,0) -> 0.59623746 | E13: =IFERROR(B13/Calculations!$B$9,0) -> 0.25147183
A14: Cold Beverages | B14: =SUMIFS(Cleaned_Data!$H$5:$H$201,Cleaned_Data!$E$5:$E$201,A14,Cleaned_Data!$O$5:$O$201,"Completed") -> 14960 | C14: =SUMIFS(Cleaned_Data!$J$5:$J$201,Cleaned_Data!$E$5:$E$201,A14,Cleaned_Data!$O$5:$O$201,"Completed") -> 8623 | D14: =IFERROR(C14/B14,0) -> 0.57640374 | E14: =IFERROR(B14/Calculations!$B$9,0) -> 0.31455004
A15: Bakery | B15: =SUMIFS(Cleaned_Data!$H$5:$H$201,Cleaned_Data!$E$5:$E$201,A15,Cleaned_Data!$O$5:$O$201,"Completed") -> 10750 | C15: =SUMIFS(Cleaned_Data!$J$5:$J$201,Cleaned_Data!$E$5:$E$201,A15,Cleaned_Data!$O$5:$O$201,"Completed") -> 5776 | D15: =IFERROR(C15/B15,0) -> 0.53730233 | E15: =IFERROR(B15/Calculations!$B$9,0) -> 0.22603028
A16: Snacks | B16: =SUMIFS(Cleaned_Data!$H$5:$H$201,Cleaned_Data!$E$5:$E$201,A16,Cleaned_Data!$O$5:$O$201,"Completed") -> 9890 | C16: =SUMIFS(Cleaned_Data!$J$5:$J$201,Cleaned_Data!$E$5:$E$201,A16,Cleaned_Data!$O$5:$O$201,"Completed") -> 5069 | D16: =IFERROR(C16/B16,0) -> 0.51253792 | E16: =IFERROR(B16/Calculations!$B$9,0) -> 0.20794786
A19: 3. Sales by Outlet (Rows: Outlet | Values: Sum of Sales, Order Count)
A20: Outlet | B20: Sales | C20: Orders | D20: % of Total Sales
A21: Koramangala | B21: =SUMIFS(Cleaned_Data!$H$5:$H$201,Cleaned_Data!$C$5:$C$201,A21,Cleaned_Data!$O$5:$O$201,"Completed") -> 12540 | C21: =COUNTIFS(Cleaned_Data!$C$5:$C$201,A21,Cleaned_Data!$O$5:$O$201,"Completed") -> 49 | D21: =IFERROR(B21/Calculations!$B$9,0) -> 0.26366695
A22: Indiranagar | B22: =SUMIFS(Cleaned_Data!$H$5:$H$201,Cleaned_Data!$C$5:$C$201,A22,Cleaned_Data!$O$5:$O$201,"Completed") -> 12210 | C22: =COUNTIFS(Cleaned_Data!$C$5:$C$201,A22,Cleaned_Data!$O$5:$O$201,"Completed") -> 42 | D22: =IFERROR(B22/Calculations!$B$9,0) -> 0.25672834
A23: Whitefield | B23: =SUMIFS(Cleaned_Data!$H$5:$H$201,Cleaned_Data!$C$5:$C$201,A23,Cleaned_Data!$O$5:$O$201,"Completed") -> 12580 | C23: =COUNTIFS(Cleaned_Data!$C$5:$C$201,A23,Cleaned_Data!$O$5:$O$201,"Completed") -> 42 | D23: =IFERROR(B23/Calculations!$B$9,0) -> 0.26450799
A24: HSR Layout | B24: =SUMIFS(Cleaned_Data!$H$5:$H$201,Cleaned_Data!$C$5:$C$201,A24,Cleaned_Data!$O$5:$O$201,"Completed") -> 10230 | C24: =COUNTIFS(Cleaned_Data!$C$5:$C$201,A24,Cleaned_Data!$O$5:$O$201,"Completed") -> 37 | D24: =IFERROR(B24/Calculations!$B$9,0) -> 0.21509672
A27: 4. Top 5 Products by Sales
A28: Product | B28: Sales
A29: Frappe | B29: =SUMIFS(Cleaned_Data!$H$5:$H$201,Cleaned_Data!$D$5:$D$201,A29,Cleaned_Data!$O$5:$O$201,"Completed") -> 6960
A30: Sandwich | B30: =SUMIFS(Cleaned_Data!$H$5:$H$201,Cleaned_Data!$D$5:$D$201,A30,Cleaned_Data!$O$5:$O$201,"Completed") -> 3800
A31: Latte | B31: =SUMIFS(Cleaned_Data!$H$5:$H$201,Cleaned_Data!$D$5:$D$201,A31,Cleaned_Data!$O$5:$O$201,"Completed") -> 3800
A32: Danish Pastry | B32: =SUMIFS(Cleaned_Data!$H$5:$H$201,Cleaned_Data!$D$5:$D$201,A32,Cleaned_Data!$O$5:$O$201,"Completed") -> 3520
A33: Brownie | B33: =SUMIFS(Cleaned_Data!$H$5:$H$201,Cleaned_Data!$D$5:$D$201,A33,Cleaned_Data!$O$5:$O$201,"Completed") -> 3450
A35: Note: the 5 products above were identified as the current top performers by Sales; each cell's value is still a live SUMIFS formula, so if the underlying data changes, update this list by checking the ranking again.
A37: 5. Order Status Breakdown (Rows: Order Status | Values: Count, % of Total)
A38: Order Status | B38: Orders | C38: % of Total
A39: Completed | B39: =COUNTIF(Cleaned_Data!$O$5:$O$201,A39) -> 170 | C39: =IFERROR(B39/Calculations!$B$4,0) -> 0.86294416
A40: Cancelled | B40: =COUNTIF(Cleaned_Data!$O$5:$O$201,A40) -> 27 | C40: =IFERROR(B40/Calculations!$B$4,0) -> 0.13705584

Sheet Dashboard
B2: BrewTrack — Coffee Shop Sales Performance Dashboard
B3: Jun–Aug 2026 | 4 outlets | Data cleaned & calculated on the Cleaned_Data and Calculations tabs
B6: Total Sales | E6: Total Profit | H6: Total Orders | K6: Avg Order Value | N6: Profit Margin
B7: =Calculations!B9 -> 47560 | E7: =Calculations!B11 -> 26599 | H7: =Calculations!B4 -> 197 | K7: =Calculations!B13 -> 279.76471 | N7: =Calculations!B12 -> 0.5592725
J43: Filtering this dashboard
J44: This dashboard's charts pull from the PivotTables tab, which is formula-driven — so filtering happens on Cleaned_Data. Use the AutoFilter dropdowns on the Cleaned_Data tab (Outlet, Category, Month, Order Status) to narrow the data; the KPI cards and pivot-style tables recalculate automatically. To get one-click Slicers instead: select the Cleaned_Data table, go to Insert > PivotTable, build a PivotTable from any summary above, then Insert > Slicer.
